{"name": "not authenticated user -- @1.9 cases", "status": "failed", "statusDetails": {"message": "AssertionError\n", "trace": "  File \"c:\\users\\wsu\\pycharmprojects\\msw_api\\venv\\lib\\site-packages\\behave\\model.py\", line 1329, in run\n    match.run(runner.context)\n  File \"c:\\users\\wsu\\pycharmprojects\\msw_api\\venv\\lib\\site-packages\\behave\\matchers.py\", line 98, in run\n    self.func(context, *args, **kwargs)\n  File \"features\\steps\\reconciliation_access.py\", line 29, in step_impl\n    assert actual_result == boolean\n"}, "steps": [{"name": "Given alien makes get request: /reconciliation/reports_update/", "status": "passed", "start": 1610694036545, "stop": 1610694036579}, {"name": "Then check response of request: Authentication credentials were not provided. is True", "status": "failed", "statusDetails": {"message": "AssertionError\n", "trace": "  File \"c:\\users\\wsu\\pycharmprojects\\msw_api\\venv\\lib\\site-packages\\behave\\model.py\", line 1329, in run\n    match.run(runner.context)\n  File \"c:\\users\\wsu\\pycharmprojects\\msw_api\\venv\\lib\\site-packages\\behave\\matchers.py\", line 98, in run\n    self.func(context, *args, **kwargs)\n  File \"features\\steps\\reconciliation_access.py\", line 29, in step_impl\n    assert actual_result == boolean\n"}, "start": 1610694036579, "stop": 1610694036580}], "parameters": [{"name": "url", "value": "/reconciliation/reports_update/"}, {"name": "method", "value": "get"}, {"name": "bool", "value": "True"}], "start": 1610694036543, "stop": 1610694036580, "uuid": "7cd45f86-8cc5-4dcf-a26f-72d4faa05eef", "historyId": "ac58806490ce30707c69c23b6a43d454", "fullName": "features/III-reconciliation_access.feature:not authenticated user", "labels": [{"name": "severity", "value": "normal"}, {"name": "feature", "value": "reconciliation check access"}, {"name": "framework", "value": "behave"}, {"name": "language", "value": "cpython3"}]}