{"name": "not authenticated user -- @1.10 cases", "status": "failed", "statusDetails": {"message": "AssertionError\n", "trace": "  File \"c:\\users\\wsu\\pycharmprojects\\msw_api\\venv\\lib\\site-packages\\behave\\model.py\", line 1329, in run\n    match.run(runner.context)\n  File \"c:\\users\\wsu\\pycharmprojects\\msw_api\\venv\\lib\\site-packages\\behave\\matchers.py\", line 98, in run\n    self.func(context, *args, **kwargs)\n  File \"features\\steps\\reconciliation_access.py\", line 29, in step_impl\n    assert actual_result == boolean\n"}, "steps": [{"name": "Given alien makes post request: /reconciliation/reports_update/", "status": "passed", "start": 1610694036583, "stop": 1610694036612}, {"name": "Then check response of request: Authentication credentials were not provided. is True", "status": "failed", "statusDetails": {"message": "AssertionError\n", "trace": "  File \"c:\\users\\wsu\\pycharmprojects\\msw_api\\venv\\lib\\site-packages\\behave\\model.py\", line 1329, in run\n    match.run(runner.context)\n  File \"c:\\users\\wsu\\pycharmprojects\\msw_api\\venv\\lib\\site-packages\\behave\\matchers.py\", line 98, in run\n    self.func(context, *args, **kwargs)\n  File \"features\\steps\\reconciliation_access.py\", line 29, in step_impl\n    assert actual_result == boolean\n"}, "start": 1610694036612, "stop": 1610694036615}], "parameters": [{"name": "url", "value": "/reconciliation/reports_update/"}, {"name": "method", "value": "post"}, {"name": "bool", "value": "True"}], "start": 1610694036582, "stop": 1610694036616, "uuid": "73a37303-d571-4b24-bcfb-525696c70ff9", "historyId": "9678365b203b9eeb5afccf65c6db932d", "fullName": "features/III-reconciliation_access.feature:not authenticated user", "labels": [{"name": "severity", "value": "normal"}, {"name": "feature", "value": "reconciliation check access"}, {"name": "framework", "value": "behave"}, {"name": "language", "value": "cpython3"}]}