{"name": "check hr import", "status": "broken", "statusDetails": {"message": "TypeError: '<' not supported between instances of 'dict' and 'dict'\n", "trace": "  File \"c:\\users\\wsu\\pycharmprojects\\msw_api\\venv\\lib\\site-packages\\behave\\model.py\", line 1329, in run\n    match.run(runner.context)\n  File \"c:\\users\\wsu\\pycharmprojects\\msw_api\\venv\\lib\\site-packages\\behave\\matchers.py\", line 98, in run\n    self.func(context, *args, **kwargs)\n  File \"features\\steps\\reconciliation_II.py\", line 212, in step_impl\n    context.actual_result = result[:-1].sort()\n"}, "steps": [{"name": "Given download all_users_data.xlsx", "status": "passed", "start": 1610713928609, "stop": 1610713929162}, {"name": "When parse downloaded all_users_data.xlsx to compare with data from /reconciliation/all_users_data/", "status": "broken", "statusDetails": {"message": "TypeError: '<' not supported between instances of 'dict' and 'dict'\n", "trace": "  File \"c:\\users\\wsu\\pycharmprojects\\msw_api\\venv\\lib\\site-packages\\behave\\model.py\", line 1329, in run\n    match.run(runner.context)\n  File \"c:\\users\\wsu\\pycharmprojects\\msw_api\\venv\\lib\\site-packages\\behave\\matchers.py\", line 98, in run\n    self.func(context, *args, **kwargs)\n  File \"features\\steps\\reconciliation_II.py\", line 212, in step_impl\n    context.actual_result = result[:-1].sort()\n"}, "start": 1610713929163, "stop": 1610713929206}], "start": 1610713928606, "stop": 1610713929207, "uuid": "a6a7f6dc-3329-4467-8f6d-f829db11ef0c", "historyId": "f0498b976f875a2b28959ccfe3337637", "fullName": "features/II-reconciliation_risk.feature:check hr import", "labels": [{"name": "severity", "value": "normal"}, {"name": "tag", "value": "manager_user"}, {"name": "tag", "value": "super_user"}, {"name": "feature", "value": "check all user_data"}, {"name": "framework", "value": "behave"}, {"name": "language", "value": "cpython3"}]}