{"name": "not authenticated user -- @1.5 cases", "status": "failed", "statusDetails": {"message": "AssertionError\n", "trace": "  File \"c:\\users\\wsu\\pycharmprojects\\msw_api\\venv\\lib\\site-packages\\behave\\model.py\", line 1329, in run\n    match.run(runner.context)\n  File \"c:\\users\\wsu\\pycharmprojects\\msw_api\\venv\\lib\\site-packages\\behave\\matchers.py\", line 98, in run\n    self.func(context, *args, **kwargs)\n  File \"features\\steps\\reconciliation_access.py\", line 29, in step_impl\n    assert actual_result == boolean\n"}, "steps": [{"name": "Given alien makes post request: /reconciliation/date_of_reconciliation/", "status": "passed", "start": 1610694036422, "stop": 1610694036448}, {"name": "Then check response of request: Authentication credentials were not provided. is True", "status": "failed", "statusDetails": {"message": "AssertionError\n", "trace": "  File \"c:\\users\\wsu\\pycharmprojects\\msw_api\\venv\\lib\\site-packages\\behave\\model.py\", line 1329, in run\n    match.run(runner.context)\n  File \"c:\\users\\wsu\\pycharmprojects\\msw_api\\venv\\lib\\site-packages\\behave\\matchers.py\", line 98, in run\n    self.func(context, *args, **kwargs)\n  File \"features\\steps\\reconciliation_access.py\", line 29, in step_impl\n    assert actual_result == boolean\n"}, "start": 1610694036448, "stop": 1610694036449}], "parameters": [{"name": "url", "value": "/reconciliation/date_of_reconciliation/"}, {"name": "method", "value": "post"}, {"name": "bool", "value": "True"}], "start": 1610694036421, "stop": 1610694036449, "uuid": "922fde9d-eb2a-427a-aaee-ab6d3faa35f1", "historyId": "b93ce10c8d9ef20b08afc13d9d62650a", "fullName": "features/III-reconciliation_access.feature:not authenticated user", "labels": [{"name": "severity", "value": "normal"}, {"name": "feature", "value": "reconciliation check access"}, {"name": "framework", "value": "behave"}, {"name": "language", "value": "cpython3"}]}